Workbook

Sheet 112日記帳
A1: 112年日記帳
A2: 月 | B2: 日 | C2: 摘要 | D2: 收入 | E2: 支出 | F2: 餘額 | G2: 備註
A3: 1 | B3: 1 | C3: 111年餘額 | F3: 165104 | G3: 112/1/3
A4: 1 | B4: 5 | C4: 製作海報印刷費 | E4: 1470 | F4: =F3+D4-E4 -> 163634
A5: 1 | B5: 7 | C5: 銀行收入-方炳崴月費 | D5: 1600 | F5: =F4+D5-E5 -> 165234
A6: 1 | B6: 9 | C6: 銀行收入-黃裕傑月費 | D6: 1600 | F6: =F5+D6-E6 -> 166834
A7: 1 | B7: 10 | C7: 銀行收入-曾浩恩、孫瑋程月費 | D7: =1600+1600 -> 3200 | F7: =F6+D7-E7 -> 170034
A8: 1 | B8: 10 | C8: 銀行收入-劉思澄月費 | D8: 1500 | F8: =F7+D8-E8 -> 171534
A9: 1 | B9: 11 | C9: 銀行收入-黃貞喜月費 | D9: 1600 | F9: =F8+D9-E9 -> 173134 | G9: 無學費袋繳回
A10: 1 | B10: 12 | C10: 銀行收入-顏椲珣月費 | D10: 1600 | F10: =F9+D10-E10 -> 174734 | G10: 無學費袋繳回
A11: 1 | B11: 13 | C11: 銀行收入-施沛平月費 | D11: 1600 | F11: =F10+D11-E11 -> 176334
A12: 1 | B12: 13 | C12: 銀行收入-趙珩聿月費 | D12: 1600 | F12: =F11+D12-E12 -> 177934
A13: 1 | B13: 16 | C13: 銀行收入-廖楷淯月費 | D13: 1600 | F13: =F12+D13-E13 -> 179534
A14: 1 | B14: 16 | C14: 銀行收入-羅宥晴月費 | D14: 1600 | F14: =F13+D14-E14 -> 181134
A15: 1 | B15: 18 | C15: 銀行支出-教練春節禮盒*3人 | E15: 1575 | F15: =F14+D15-E15 -> 179559
A16: 1 | B16: 18 | C16: 現金支出-教練春節紅包2000*5人 | E16: 10000 | F16: =F15+D16-E16 -> 169559
A17: 1 | B17: 18 | C17: 銀行收入-張元祈月費 | D17: 1500 | F17: =F16+D17-E17 -> 171059
A18: 1 | B18: 18 | C18: 現金收入-月費一批 | D18: =63300+1600 -> 64900 | F18: =F17+D18-E18 -> 235959
A19: 1 | B19: 20 | C19: 1月教練薪資(含匯費) | E19: 92687 | F19: =F18+D19-E19 -> 143272
A20: 1 | B20: 27 | C20: 現金收入-劉貞妤月費 | D20: 1500 | F20: =F19+D20-E20 -> 144772
A21: 1 | B21: 29 | C21: 現金收入-許珈甄、許晴寧月費 | D21: 3100 | F21: =F20+D21-E21 -> 147872
A22: 1 | B22: 30 | C22: 現金收入-葉清寶 | D22: 1600 | F22: =F21+D22-E22 -> 149472
A23: 1 | B23: 30 | C23: 銀行收入-曾浩恩、羅宥睛、黃裕傑、趙珩聿、黃貞喜 | D23: =3500*4+2800*1 -> 16800 | F23: =F22+D23-E23 -> 166272
A24: 1 | B24: 31 | C24: 現金收入-劉思澄 | D24: 3500 | F24: =F23+D24-E24 -> 169772
A25: 2 | B25: 1 | C25: 銀行收入-方炳崴、顏椲珣 | D25: =3500*2 -> 7000 | F25: =F24+D25-E25 -> 176772
A26: 2 | B26: 2 | C26: 銀行收入-黃圓量 | D26: 600 | F26: =F25+D26-E26 -> 177372
A27: 2 | B27: 6 | C27: 銀行收入-廖楷淯月費 | D27: 3500 | F27: =F26+D27-E27 -> 180872
A28: 2 | B28: 13 | C28: 獎金-(嵐星盃30000+歐克盃10200)/2 | D28: 21000 | F28: =F27+D28-E28 -> 201872
A29: 2 | B29: 13 | C29: 現金收入-寒訓一批 | D29: 159600 | F29: =F28+D29-E29 -> 361472
A30: 2 | B30: 13 | C30: 銀行收入-施沛平、張元祈 | D30: =3500*2 -> 7000 | F30: =F29+D30-E30 -> 368472
A31: 2 | B31: 13 | C31: 現金支出-慶生蛋糕 | E31: 1400 | F31: =F30+D31-E31 -> 367072
A32: 2 | B32: 16 | C32: 銀行支出-歐克盃教練交通費 | E32: =706*2+1000 -> 2412 | F32: =F31+D32-E32 -> 364660
A33: 2 | B33: 16 | C33: 銀行支出-歐克盃中餐及晚餐費用 | E33: 1722 | F33: =F32+D33-E33 -> 362938
A34: 2 | B34: 16 | C34: 銀行支出-嵐星盃教練交通費 | E34: 824 | F34: =F33+D34-E34 -> 362114
A35: 2 | B35: 16 | C35: 銀行支出-嵐星盃餐費 | E35: 800 | F35: =F34+D35-E35 -> 361314
A36: 2 | B36: 16 | C36: 銀行支出-招生單影印費用 | E36: 1000 | F36: =F35+D36-E36 -> 360314
A37: 2 | B37: 17 | C37: 現金支出-歐克盃及嵐星盃選手獎勵金700*2 | E37: 1400 | F37: =F36+D37-E37 -> 358914
A38: 2 | B38: 18 | C38: 銀行收入-曾浩恩、黃裕傑、方炳崴 | D38: =1800*3 -> 5400 | F38: =F37+D38-E38 -> 364314
A39: 2 | B39: 20 | C39: 銀行收入-顏椲珣、趙珩聿、黃貞喜 | D39: =1800*3 -> 5400 | F39: =F38+D39-E39 -> 369714
A40: 2 | B40: 21 | C40: 銀行收入-施沛平 | D40: 1800 | F40: =F39+D40-E40 -> 371514
...

Sheet 112收支表 
A1: 112年度收支表
A2: 112年度收支表 | B2: 1月 | C2: 2月+寒訓 | D2: 3月 | E2: 4月 | F2: 5月 | G2: 6月 | H2: 7月 | I2: 8月 | J2: 9月 | K2: 10月 | L2: 11月 | M2: 12月 | N2: 總計 | O2: 比率
A3: 學費收入 | B3: 90100 | C3: =繳費名單!G110+繳費名單!F110 -> 299000 | D3: =繳費名單!H110 -> 147600 | E3: =繳費名單!I110 -> 159800 | F3: =繳費名單!J110 -> 162200 | G3: =繳費名單!K110 -> 136700 | H3: =繳費名單!L110 -> 273000 | I3: =繳費名單!M110 -> 238800 | J3: 153600 | K3: =繳費名單!O110 -> 168100 | L3: =繳費名單!P110 -> 177800 | M3: 162200 | N3: =SUM(B3:M3) -> 2168900 | O3: =N3/$N$5 -> 0.97941066
A4: 其他收入 | B4: 0 | C4: 21000 | D4: 6000 | E4: 700 | F4: =2100+6750+4800 -> 13650 | G4: 665 | K4: 1500 | L4: 600 | M4: 1480 | N4: =SUM(B4:M4) -> 45595 | O4: =N4/$N$5 -> 0.020589344
A5: 收入總額 | B5: =B3+B4 -> 90100 | C5: =C3+C4 -> 320000 | D5: =D3+D4 -> 153600 | E5: =E3+E4 -> 160500 | F5: =F3+F4 -> 175850 | G5: =G3+G4 -> 137365 | H5: =H3+H4 -> 273000 | I5: 238800 | J5: 153600 | K5: 169600 | L5: 178400 | M5: 163680 | N5: =SUM(B5:M5) -> 2214495 | O5: 1
A6: 薪資支出 | B6: 92687 | C6: =教練薪資!D17 -> 225042 | D6: =教練薪資!E17 -> 140280 | E6: =教練薪資!F17 -> 118420 | F6: =教練薪資!G17 -> 138735 | G6: =教練薪資!H17 -> 135640 | H6: =教練薪資!I17 -> 216190 | I6: 265125 | J6: =教練薪資!K17 -> 162575 | K6: =教練薪資!L17 -> 146175 | L6: 125645 | M6: 131870 | N6: =SUM(B6:M6) -> 1898384 | O6: =N6/$N$5 -> 0.85725369
A7: 文具用品 | G7: 120 | N7: =SUM(B7:M7) -> 120 | O7: =N7/$N$5 -> 5.4188427e-05
A8: 差旅費 | N8: =SUM(B8:M8) -> 0 | O8: =N8/$N$5 -> 0
A9: 郵電費 | N9: =SUM(B9:M9) -> 0 | O9: =N9/$N$5 -> 0
A10: 修繕費 | N10: =SUM(B10:M10) -> 0 | O10: =N10/$N$5 -> 0
A11: 電費 | F11: =352+570 -> 922 | H11: 846 | M11: 4448 | N11: =SUM(B11:M11) -> 6216 | O11: =N11/$N$5 -> 0.0028069605
A12: 暫付款 | G12: 25000 | H12: -25000 | N12: =SUM(B12:M12) -> 0 | O12: =N12/$N$5 -> 0
A13: 交通費 | C13: 3236 | F13: 6446 | I13: 11550 | J13: 9515 | L13: 2920 | M13: 8400 | N13: =SUM(B13:M13) -> 42067 | O13: =N13/$N$5 -> 0.018996205
A14: 餐費(宿) | C14: 2522 | F14: =2700+1040 -> 3740 | I14: 13860 | J14: 12062 | L14: 3660 | N14: =SUM(B14:M14) -> 35844 | O14: =N14/$N$5 -> 0.016186083
A15: 訓練費(球) | N15: =SUM(B15:M15) -> 0 | O15: =N15/$N$5 -> 0
A16: 獎金支出 | B16: 11575 | C16: 1400 | D16: 20000 | E16: 1400 | F16: 500 | G16: =10000+5000+8000 -> 23000 | M16: 9800 | N16: =SUM(B16:M16) -> 67675 | O16: =N16/$N$5 -> 0.030560015
A17: 其他費用 | B17: 1470 | C17: =1000+1400 -> 2400 | D17: 1400 | E17: =1400+60 -> 1460 | F17: ='112日記帳'!E91+'112日記帳'!E83+'112日記帳'!E102 -> 5080 | G17: =1400+630+400+2550 -> 4980 | H17: =1400+4500 -> 5900 | I17: 2915 | J17: 13600 | K17: 6640 | L17: 2345 | M17: 6920 | N17: =SUM(B17:M17) -> 55110 | O17: =N17/$N$5 -> 0.024886035
A18: 支出總額 | B18: =SUM(B6:B17) -> 105732 | C18: =SUM(C6:C17) -> 234600 | D18: =SUM(D6:D17) -> 161680 | E18: =SUM(E6:E17) -> 121280 | F18: =SUM(F6:F17) -> 155423 | G18: =SUM(G6:G17) -> 188740 | H18: =SUM(H6:H17) -> 197936 | I18: 293450 | J18: =SUM(J6:J17) -> 197752 | K18: =SUM(K6:K17) -> 152815 | L18: =SUM(L6:L17) -> 134570 | M18: =SUM(M6:M17) -> 161438 | N18: =SUM(B18:M18) -> 2105416 | O18: =N18/$N$5 -> 0.95074317
A19: 收支相抵 | B19: =B5-B18 -> -15632 | C19: =C5-C18 -> 85400 | D19: =D5-D18 -> -8080 | E19: =E5-E18 -> 39220 | F19: =F5-F18 -> 20427 | G19: =G5-G18 -> -51375 | H19: =H5-H18 -> 75064 | I19: -54650 | J19: =J5-J18 -> -44152 | K19: =K5-K18 -> 16785 | L19: =L5-L18 -> 43830 | M19: =M5-M18 -> 2242 | N19: =N5-N18 -> 109079 | O19: =N19/$N$5 -> 0.049256828
A20: 上年度結餘165104元 | B20: =165104+B19 -> 149472 | C20: =B20+C19 -> 234872 | D20: =C20+D19 -> 226792 | E20: =D20+E19 -> 266012 | F20: =E20+F19 -> 286439 | G20: =F20+G19 -> 235064 | H20: =G20+H19 -> 310128 | I20: =I19+H20 -> 255478 | J20: =J19+I20 -> 211326 | K20: 228111 | L20: =L19+K20 -> 271941 | M20: 274183

Sheet 比賽費用支出
A1: 月 | B1: 日 | C1: 摘要 | D1: 收入 | E1: 支出 | F1: 總計 | G1: 備註
A2: 2 | C2: 歐克盃冠軍 | D2: =30000/2 -> 15000
C3: 嵐星嵐冠軍 | D3: =12000/2 -> 6000 | I3: ＋
C4: 歐克盃餐費 | E4: =1530+96+96 -> 1722
C5: 歐克盃教練交通費 | E5: =706*2+1000 -> 2412
C6: 嵐星嵐餐費 | E6: 800
C7: 嵐星嵐交通費 | E7: 824
F8: =D2+D3-SUM(E4:E8) -> 15242
A9: 5 | B9: 11 | C9: 自由盃團體賽-報名費 | E9: 3500
C10: 自由盃團體賽-5/11餐費 | E10: =80*13 -> 1040
C11: 自由盃團體賽-教練交通費 | E11: 6446
C12: 自由盃團體賽-住宿補助9人*300 | E12: 2700
F13: =SUM(E9:E13) -> 13686
A14: 8 | C14: 南區精英賽車資 | E14: 11550 | G14: 8/2-8/5
C15: 南區精英賽餐費 | E15: =4510+4080+2720+2550 -> 13860 | G15: 8/2-8/5
F17: =E14+E15+E16 -> 25410
A18: 9 | B18: 9 | C18: 議長盃團體賽交通費 | E18: 3675
A19: 9 | B19: 9 | C19: 議長盃團體賽餐費 | E19: 3740
A20: 9 | B20: 18 | C20: 總統盃團體賽2組報名費 | E20: 1200 | G20: 9/18-9/21
A21: 9 | B21: 19 | C21: 總統盃團體賽組-選手12名*300住宿費補貼 | E21: 3600 | G21: 9/18-9/21
A22: 9 | B22: 19 | C22: 總統盃團體賽教練2名餐宿+交通費 | E22: 10562 | G22: 9/18-9/21
F24: 22777
A25: 11 | B25: 23 | C25: 諸羅山盃午餐費 | E25: 800
A26: 11 | B26: 28 | C26: 一銀盃錦標賽-選手6名*300住宿補貼 | E26: 1800
A27: 11 | B27: 28 | C27: 一銀盃錦標賽-教練1名餐宿+交通費 | E27: 3980
F28: 6580
A29: 12 | B29: 1 | C29: 生達盃交通費 | E29: 8400 | G29: 12/1~12/2
A30: 12 | B30: 23 | C30: 諸羅山盃-教練團獎金 | E30: 4000 | G30: 11/23
A31: 12 | B31: 23 | C31: 體促會-教練團獎金 | E31: 4000 | G31: 12/9~12/10
A32: 12 | B32: 23 | C32: 體促會-選手獎金18名*100 | E32: 1800 | F32: 18200 | G32: 12/9~12/10

Sheet 繳費名單
A1: 年級 | B1: 班別 | C1: 順序 | D1: 學生姓名 | E1: 一月 | F1: 寒訓 | G1: 二月 | H1: 三月 | I1: 四月 | J1: 五月 | K1: 六月 | L1: 七月暑訓 | M1: 八月暑訓 | N1: 九月 | O1: 十月 | P1: 十一月 | Q1: 十二月 | R1: 總計
A2: 6 | D2: 方炳崴 | E2: 1600 | F2: 3500 | G2: 1800 | H2: 2500 | I2: 2500 | J2: 2500 | K2: 畢業 | L2: 畢業 | M2: 畢業 | N2: 畢業 | O2: 畢業 | P2: 畢業 | Q2: 畢業 | R2: =SUM(E2:Q2) -> 14400
A3: 6 | D3: 黃柏洋 | E3: 1600 | F3: 3500 | G3: 1800 | H3: 2500 | I3: 2500 | J3: 2500 | K3: 畢業 | L3: 畢業 | M3: 畢業 | N3: 畢業 | O3: 畢業 | P3: 畢業 | Q3: 畢業 | R3: =SUM(E3:Q3) -> 14400
A4: 6 | D4: 陳秉宏 | E4: 1600 | F4: 3500 | G4: 1800 | H4: 2500 | I4: 2500 | J4: 2500 | K4: 畢業 | L4: 畢業 | M4: 畢業 | N4: 畢業 | O4: 畢業 | P4: 畢業 | Q4: 畢業 | R4: =SUM(E4:Q4) -> 14400
A5: 6 | D5: 陳秉承 | E5: 1600 | F5: 3500 | G5: 1800 | H5: 2500 | I5: 2500 | J5: 2500 | K5: 畢業 | L5: 畢業 | M5: 畢業 | N5: 畢業 | O5: 畢業 | P5: 畢業 | Q5: 畢業 | R5: =SUM(E5:Q5) -> 14400
A6: 6 | D6: 曾浩恩 | E6: 1600 | F6: 3500 | G6: 1800 | H6: 2500 | I6: 2500 | J6: 2500 | K6: 畢業 | L6: 畢業 | M6: 畢業 | N6: 畢業 | O6: 畢業 | P6: 畢業 | Q6: 畢業 | R6: =SUM(E6:Q6) -> 14400
A7: 6 | D7: 林大棋 | E7: 1600 | F7: 3500 | G7: 1800 | H7: 2500 | I7: 2500 | J7: 2500 | K7: 畢業 | L7: 畢業 | M7: 畢業 | N7: 畢業 | O7: 畢業 | P7: 畢業 | Q7: 畢業 | R7: =SUM(E7:Q7) -> 14400
A8: 6 | D8: 賴宥達 | E8: 1600 | F8: 3500 | G8: 1800 | H8: 2500 | I8: 2500 | J8: 2500 | K8: 畢業 | L8: 畢業 | M8: 畢業 | N8: 畢業 | O8: 畢業 | P8: 畢業 | Q8: 畢業 | R8: =SUM(E8:Q8) -> 14400
A9: 6 | D9: 黃裕傑 | E9: 1600 | F9: 3500 | G9: 1800 | H9: 2500 | I9: 2500 | J9: 2500 | K9: 畢業 | L9: 畢業 | M9: 畢業 | N9: 畢業 | O9: 畢業 | P9: 畢業 | Q9: 畢業 | R9: =SUM(E9:Q9) -> 14400
A10: 6 | D10: 蔡冠昇 | E10: 1600 | F10: 3500 | G10: 1800 | H10: 2500 | I10: 2500 | J10: 2500 | K10: 畢業 | L10: 畢業 | M10: 畢業 | N10: 畢業 | O10: 畢業 | P10: 畢業 | Q10: 畢業 | R10: =SUM(E10:Q10) -> 14400
A11: 6 | D11: 王以樂 | E11: 1600 | F11: 3500 | G11: 1800 | H11: 2500 | I11: 2500 | J11: 2500 | K11: 畢業 | L11: 畢業 | M11: 畢業 | N11: 畢業 | O11: 畢業 | P11: 畢業 | Q11: 畢業 | R11: =SUM(E11:Q11) -> 14400
A12: 5 | C12: 12 | D12: 羅宥晴 | E12: 1600 | F12: 3500 | G12: 1800 | H12: 2500 | I12: 2500 | J12: 2500 | K12: 2500 | L12: 5000 | M12: 5000 | N12: 2800 | O12: 11月繳 | P12: 5000 | R12: =SUM(E12:Q12) -> 34700
A13: 5 | C13: 13 | D13: 賴胤丞 | E13: 1500 | F13: 3500 | G13: 1700 | H13: 2400 | I13: 2400 | J13: 2400 | K13: 2400 | L13: 未參加 | M13: 未參加 | N13: 2700 | O13: 2500 | P13: 2500 | Q13: 2500 | R13: =SUM(E13:Q13) -> 26500
A14: 5 | C14: 14 | D14: 劉宇恩 | E14: 1600 | F14: 3500 | G14: 1800 | H14: 2500 | I14: 2500 | J14: 2500 | K14: 2500 | L14: 5000 | M14: 5000 | N14: 2800 | O14: 2500 | P14: 2500 | Q14: 2500 | R14: =SUM(E14:Q14) -> 37200
A15: 5 | C15: 15 | D15: 許珀學 | E15: 1600 | F15: 3500 | G15: 1800 | H15: 2500 | I15: 2500 | J15: 2500 | K15: 2500 | L15: 5000 | M15: 5000 | N15: 2800 | O15: 2500 | P15: 2500 | Q15: 2500 | R15: =SUM(E15:Q15) -> 37200
A16: 5 | C16: 16 | D16: 林緖煌 | E16: 1600 | F16: 3500 | G16: 1800 | H16: 2500 | I16: 2500 | J16: 2500 | K16: 2500 | L16: 5000 | M16: 5000 | N16: 10月繳 | O16: 5300 | P16: 2500 | Q16: 2500 | R16: =SUM(E16:Q16) -> 37200
A17: 5 | C17: 17 | D17: 趙珩聿 | E17: 1600 | F17: 3500 | G17: 1800 | H17: 2500 | I17: 2500 | J17: 2500 | K17: 2500 | L17: 5000 | M17: 5000 | N17: 2800 | O17: 2500 | P17: 2500 | Q17: 2500 | R17: =SUM(E17:Q17) -> 37200
A18: 5 | C18: 18 | D18: 陳妍禎 | E18: 1600 | F18: 3500 | G18: 1800 | H18: 2500 | I18: 2500 | J18: 2500 | K18: 2500 | L18: 5000 | M18: 5000 | N18: 10月繳 | O18: 5300 | P18: 2500 | Q18: 2500 | R18: =SUM(E18:Q18) -> 37200
C19: 19 | D19: 吳澐叡 | E19: 1600 | F19: 2800 | G19: 受傷未收 | H19: 4月繳 | I19: =2800+2500 -> 5300 | J19: 2500 | K19: 2500 | L19: 3500 | M19: 未參加 | N19: 2800 | O19: 2500 | P19: 2500 | Q19: 2500 | R19: =SUM(E19:Q19) -> 28500
A20: 4 | C20: 20 | D20: 吳昀霏 | E20: 1500 | F20: 3500 | G20: 1700 | H20: 2400 | I20: 2400 | J20: 2400 | K20: 2400 | L20: 5000 | M20: 5000 | N20: 2700 | O20: 2500 | P20: 2500 | Q20: 2500 | R20: =SUM(E20:Q20) -> 36500
C21: 21 | D21: 蘇品云 | E21: 1600 | F21: 3500 | G21: 1800 | H21: 2500 | I21: 2500 | J21: 2500 | K21: 2500 | L21: 5000 | M21: 5000 | N21: 2800 | O21: 2500 | P21: 2500 | Q21: 2500 | R21: =SUM(E21:Q21) -> 37200
A22: 4 | C22: 22 | D22: 蘇子承 | E22: 1600 | F22: 3500 | G22: 1800 | H22: 2500 | I22: 2500 | J22: 2500 | K22: 2500 | L22: 3500 | M22: 3500 | N22: 2800 | O22: 2500 | P22: 2500 | Q22: 2500 | R22: =SUM(E22:Q22) -> 34200
A23: 4 | C23: 23 | D23: 歐于瑄 | E23: 1600 | F23: 3500 | G23: 1800 | H23: 2500 | I23: 2500 | J23: 2500 | K23: 2500 | L23: 5000 | M23: 5000 | N23: 10月繳 | O23: 5300 | P23: 2500 | Q23: 2500 | R23: =SUM(E23:Q23) -> 37200
A24: 4 | C24: 24 | D24: 高湘惟 | E24: 1600 | F24: 3500 | G24: 3月繳 | H24: =2400+1700 -> 4100 | I24: 2400 | J24: 2400 | K24: 2400 | L24: 5000 | M24: 5000 | N24: 2700 | O24: 2400 | P24: 2400 | Q24: 2400 | R24: =SUM(E24:Q24) -> 36300
A25: 4 | C25: 25 | D25: 張元祈 | E25: 1500 | F25: 3500 | G25: 1700 | H25: 2400 | I25: 2400 | J25: 2400 | K25: 2400 | L25: 5000 | M25: 5000 | N25: 2700 | O25: 2400 | P25: 2400 | Q25: 2400 | R25: =SUM(E25:Q25) -> 36200
A26: 4 | C26: 26 | D26: 莊秉衡 | E26: 1600 | F26: 3500 | G26: 1800 | H26: 2500 | I26: 2500 | J26: 2500 | K26: 2500 | L26: 5000 | M26: 5000 | N26: 2800 | O26: 2500 | P26: 2500 | Q26: 2500 | R26: =SUM(E26:Q26) -> 37200
C27: 27 | D27: 林昱琁 | E27: 骨折未收 | F27: 3500 | G27: 1800 | H27: 2500 | I27: 2500 | J27: 2500 | K27: 2500 | L27: 3500 | M27: 3500 | N27: 2800 | O27: 11月繳 | P27: 5000 | Q27: 2500 | R27: =SUM(E27:Q27) -> 32600
A28: 2 | C28: 28 | D28: 林逸芮 | E28: 1600 | F28: 3500 | G28: 1800 | H28: 2500 | I28: 2500 | J28: 2500 | K28: 2500 | L28: 3500 | M28: 3500 | N28: 2800 | O28: 11月繳 | P28: 5000 | Q28: 2500 | R28: =SUM(E28:Q28) -> 34200
C29: 29 | D29: 劉履善 | E29: 1600 | F29: 2800 | G29: 1800 | H29: 2500 | I29: 2500 | J29: 2500 | K29: 2500 | L29: 3500 | M29: 3500 | N29: 2800 | O29: 2500 | P29: 2500 | Q29: 2500 | R29: =SUM(E29:Q29) -> 33500
A30: 3 | C30: 30 | D30: 劉思澄 | E30: 1500 | F30: 3500 | G30: 1700 | H30: 2400 | I30: 2400 | J30: 2400 | K30: 2400 | L30: 5000 | M30: 5000 | N30: 2700 | O30: 2500 | P30: 2500 | Q30: 2500 | R30: =SUM(E30:Q30) -> 36500
C31: 31 | D31: 顏敬恆 | E31: 1600 | F31: 2800 | G31: 1800 | H31: 2500 | I31: 2500 | J31: 2500 | K31: 2500 | L31: 3500 | M31: 3500 | N31: 2800 | O31: 2500 | P31: 2500 | Q31: 2500 | R31: =SUM(E31:Q31) -> 33500
C32: 32 | D32: 顏敬庭 | E32: 1600 | F32: 2800 | G32: 1800 | H32: 2500 | I32: 2500 | J32: 2500 | K32: 2500 | L32: 3500 | M32: 3500 | N32: 2800 | O32: 2500 | P32: 2500 | Q32: 2500 | R32: =SUM(E32:Q32) -> 33500
A33: 3 | C33: 33 | D33: 盧易宏 | E33: 1600 | F33: 3500 | G33: 1800 | H33: 2500 | I33: 2500 | J33: 2500 | K33: 2500 | L33: 3500 | M33: 5000 | N33: 2800 | O33: 2500 | P33: 2500 | Q33: 2500 | R33: =SUM(E33:Q33) -> 35700
A34: 3 | C34: 34 | D34: 羅子宸 | E34: 1600 | F34: 3500 | G34: 1800 | H34: 2500 | I34: 2500 | J34: 2500 | K34: 2500 | L34: 5000 | M34: 5000 | N34: 2800 | O34: 2500 | P34: 2500 | Q34: 2500 | R34: =SUM(E34:Q34) -> 37200
A35: 3 | C35: 35 | D35: 施沛平 | E35: 1600 | F35: 3500 | G35: 1800 | H35: 4月繳 | I35: 5000 | J35: 2500 | K35: 2500 | L35: 5000 | M35: 5000 | N35: 2800 | O35: 2500 | P35: 2500 | Q35: 2500 | R35: =SUM(E35:Q35) -> 37200
A36: 3 | C36: 36 | D36: 李依瑾 | E36: 1600 | F36: 3500 | G36: 1800 | H36: 2500 | I36: 2500 | J36: 2500 | K36: 2500 | L36: 5000 | M36: 5000 | N36: 2800 | O36: 2500 | P36: 2500 | Q36: 2500 | R36: =SUM(E36:Q36) -> 37200
A37: 2 | C37: 37 | D37: 林群倫 | E37: 1600 | F37: 3500 | G37: 1800 | H37: 2500 | I37: 2500 | J37: 2500 | K37: 2500 | L37: 未參加 | M37: 5000 | N37: 2800 | O37: 2500 | P37: 2500 | Q37: 2500 | R37: =SUM(E37:Q37) -> 32200
A38: 2 | C38: 38 | D38: 陳楷恩 | E38: 1600 | F38: 3500 | G38: 1800 | H38: 2500 | I38: 2500 | J38: 2500 | K38: 2500 | L38: 5000 | M38: 5000 | N38: 2800 | O38: 2500 | P38: 2500 | Q38: 2500 | R38: =SUM(E38:Q38) -> 37200
A39: 2 | C39: 39 | D39: 顏椲珣 | E39: 1600 | F39: 3500 | G39: 1800 | H39: 2500 | I39: 2500 | J39: 2500 | K39: 2500 | L39: 5000 | M39: 5000 | N39: 2800 | O39: 2500 | P39: 2500 | Q39: 2500 | R39: =SUM(E39:Q39) -> 37200
A40: 2 | C40: 40 | D40: 盧筠杰 | E40: 1600 | F40: 3500 | G40: 1800 | H40: 2500 | I40: 2500 | J40: 2500 | K40: 2500 | L40: 5000 | M40: 5000 | N40: 2800 | O40: 2500 | P40: 2500 | Q40: 2500 | R40: =SUM(E40:Q40) -> 37200
...

Sheet 教練薪資
A1: 112年教練薪資名單
A2: 項次 | B2: 教練姓名 | C2: 一月 | D2: 寒訓＋二月 | E2: 三月 | F2: 四月 | G2: 五月 | H2: 六月 | I2: 七月 | J2: 八月 | K2: 九月 | L2: 十月 | M2: 十一月 | N2: 十二月 | O2: 合計
A3: 1 | B3: 許晉得 | C3: 32078 | D3: 54257 | E3: 45600 | F3: 40100 | G3: 41500 | H3: 39700 | I3: 42800 | J3: 55761 | K3: 41500 | L3: 38800 | M3: 40300 | N3: 41200 | O3: =SUM(C3:N3) -> 513596
A4: 2 | B4: 邱鴻祥 | C4: 28184 | D4: 51050 | E4: 40500 | F4: 36300 | G4: 37200 | H4: 35300 | I4: 44350 | J4: 51089 | K4: 36400 | L4: 34400 | M4: 36700 | N4: 36600 | O4: =SUM(C4:N4) -> 468073
A5: 3 | B5: 劉威廷 | C5: 4800 | D5: 23250 | E5: 1200 | H5: 3600 | I5: 18000 | J5: 27300 | K5: 11400 | L5: 14100 | M5: 14400 | N5: 12000 | O5: =SUM(C5:N5) -> 130050
A6: 4 | B6: 羅婉玲 | C6: 9900 | D6: 28650 | E6: 18000 | F6: 14100 | G6: 19200 | H6: 19200 | I6: 25500 | J6: 32400 | K6: 22500 | L6: 14700 | M6: 10200 | N6: 11700 | O6: =SUM(C6:N6) -> 226050
A7: 5 | B7: 莊宗翰 | C7: 5400 | D7: 22350 | E7: 14700 | F7: 10500 | G7: 14400 | H7: 8700 | J7: 0 | O7: =SUM(C7:N7) -> 76050
A8: 6 | B8: 陳毅展 | C8: 5700 | D8: 22800 | E8: 3750 | F8: 4500 | G8: 6900 | H8: 7200 | I8: 22500 | J8: 24450 | K8: 3900 | L8: 3600 | N8: 2400 | O8: =SUM(C8:N8) -> 107700
A9: 7 | B9: 陳昱丞 | C9: 3900 | D9: 22650 | E9: 8700 | F9: 6600 | G9: 8700 | H9: 8100 | I9: 24750 | J9: 19200 | K9: 13500 | L9: 13200 | M9: 11700 | N9: 10800 | O9: =SUM(C9:N9) -> 151800
A10: 8 | B10: 許立臻 | E10: 7800 | F10: 6300 | G10: 10800 | H10: 13800 | I10: 21000 | J10: 30300 | K10: 14100 | L10: 11100 | M10: 12300 | N10: 16200 | O10: =SUM(C10:N10) -> 143700
A11: 9 | B11: 趙嘉甫 | I11: 17250 | J11: 24550 | K11: 19200 | L11: 16200 | N11: 900 | O11: =SUM(C11:N11) -> 78100
A12: 10 | O12: =SUM(C12:N12) -> 0
A13: 11 | O13: =SUM(C13:N13) -> 0
A14: 12 | O14: =SUM(C14:N14) -> 0
A15: 13 | O15: =SUM(C15:N15) -> 0
B16: 匯費 | C16: 25 | D16: 35 | E16: 30 | F16: 20 | G16: 35 | H16: 40 | I16: 40 | J16: 75 | K16: 75 | L16: 75 | M16: 45 | N16: 70 | O16: =SUM(C16:N16) -> 565
A17: 薪資總額 | C17: =SUM(C3:C16) -> 89987 | D17: =SUM(D3:D16) -> 225042 | E17: =SUM(E3:E16) -> 140280 | F17: =SUM(F3:F16) -> 118420 | G17: =SUM(G3:G16) -> 138735 | H17: =SUM(H3:H16) -> 135640 | I17: =SUM(I3:I16) -> 216190 | J17: =SUM(J3:J16) -> 265125 | ... L17: =SUM(L3:L16) -> 146175 | M17: 125645 | N17: =SUM(N3:N16) -> 131870 | O17: =SUM(O3:O16) -> 1895684
